<?xml version="1.0" encoding="utf-8"?>
<!-- This URDF was automatically created by SolidWorks to URDF Exporter! Originally created by Stephen Brawner (brawner@gmail.com) 
     Commit Version: 1.6.0-4-g7f85cfe  Build Version: 1.6.7995.38578
     For more information, please see http://wiki.ros.org/sw_urdf_exporter -->
<robot
  name="URDF_REV_3">
  <link
    name="base_link">
    <inertial>
      <origin
        xyz="0.642315891588275 0.970073272456656 1.271249884763"
        rpy="0 0 0" />
      <mass
        value="3.82684293584011" />
      <inertia
        ixx="0.111630335357907"
        ixy="-1.52422326805331E-09"
        ixz="-7.6211184993075E-10"
        iyy="0.149226336182957"
        iyz="7.62111684730755E-10"
        izz="0.153747873169372" />
    </inertial>
    <visual>
      <origin
        xyz="0 0 0"
        rpy="0 0 0" />
      <geometry>
        <mesh
          filename="D:\URDF\URDF_REV_3\meshes\base_link.STL" />
      </geometry>
      <material
        name="">
        <color
          rgba="0.792156862745098 0.819607843137255 0.933333333333333 1" />
      </material>
    </visual>
    <collision>
      <origin
        xyz="0 0 0"
        rpy="0 0 0" />
      <geometry>
        <mesh
          filename="D:\URDF\URDF_REV_3\meshes\base_link.STL" />
      </geometry>
    </collision>
  </link>
  <link
    name="link_1">
    <inertial>
      <origin
        xyz="0.138045726120741 0.509345674742202 0.10090595697574"
        rpy="0 0 0" />
      <mass
        value="1.84950220783011" />
      <inertia
        ixx="0.084261339784543"
        ixy="2.21887245958846E-08"
        ixz="-0.000214920023325488"
        iyy="0.00200408237808718"
        iyz="-1.51033488047982E-08"
        izz="0.0840921896907726" />
    </inertial>
    <visual>
      <origin
        xyz="0 0 0"
        rpy="0 0 0" />
      <geometry>
        <mesh
          filename="D:\URDF\URDF_REV_3\meshes\link_1.STL" />
      </geometry>
      <material
        name="">
        <color
          rgba="0.792156862745098 0.819607843137255 0.933333333333333 1" />
      </material>
    </visual>
    <collision>
      <origin
        xyz="0 0 0"
        rpy="0 0 0" />
      <geometry>
        <mesh
          filename="D:\URDF\URDF_REV_3\meshes\link_1.STL" />
      </geometry>
    </collision>
  </link>
  <joint
    name="joint_0"
    type="prismatic">
    <origin
      xyz="0.86379 -0.75279 1.3216"
      rpy="3.1416 -0.97288 0" />
    <parent
      link="base_link" />
    <child
      link="link_1" />
    <axis
      xyz="0.56292 0 0.82651" />
    <limit
      lower="0"
      upper="0"
      effort="0"
      velocity="0" />
  </joint>
  <link
    name="link_2">
    <inertial>
      <origin
        xyz="-0.210047692130392 0.101016810718501 -0.0465373857685072"
        rpy="0 0 0" />
      <mass
        value="1.43473281790559" />
      <inertia
        ixx="0.00245538605757064"
        ixy="1.60543045531972E-08"
        ixz="-0.00105985530107333"
        iyy="0.00570777198754374"
        iyz="3.45564109634258E-09"
        izz="0.00461460880554239" />
    </inertial>
    <visual>
      <origin
        xyz="0 0 0"
        rpy="0 0 0" />
      <geometry>
        <mesh
          filename="D:\URDF\URDF_REV_3\meshes\link_2.STL" />
      </geometry>
      <material
        name="">
        <color
          rgba="0.792156862745098 0.819607843137255 0.933333333333333 1" />
      </material>
    </visual>
    <collision>
      <origin
        xyz="0 0 0"
        rpy="0 0 0" />
      <geometry>
        <mesh
          filename="D:\URDF\URDF_REV_3\meshes\link_2.STL" />
      </geometry>
    </collision>
  </link>
  <joint
    name="joint_1"
    type="prismatic">
    <origin
      xyz="0.098469 0.61877 0.0013255"
      rpy="1.004 0.20162 -1.266" />
    <parent
      link="link_1" />
    <child
      link="link_2" />
    <axis
      xyz="0.93458 0 0.35574" />
    <limit
      lower="0"
      upper="0"
      effort="0"
      velocity="0" />
  </joint>
  <link
    name="link_3">
    <inertial>
      <origin
        xyz="0.665485984344828 0.501271553265247 1.26472434804176"
        rpy="0 0 0" />
      <mass
        value="1.12120959764199" />
      <inertia
        ixx="0.0784291962737404"
        ixy="-7.04439091233169E-08"
        ixz="1.42082255522166E-08"
        iyy="0.000758318944220087"
        iyz="-3.31790733044783E-10"
        izz="0.0789119917303553" />
    </inertial>
    <visual>
      <origin
        xyz="0 0 0"
        rpy="0 0 0" />
      <geometry>
        <mesh
          filename="D:\URDF\URDF_REV_3\meshes\link_3.STL" />
      </geometry>
      <material
        name="">
        <color
          rgba="0.792156862745098 0.819607843137255 0.933333333333333 1" />
      </material>
    </visual>
    <collision>
      <origin
        xyz="0 0 0"
        rpy="0 0 0" />
      <geometry>
        <mesh
          filename="D:\URDF\URDF_REV_3\meshes\link_3.STL" />
      </geometry>
    </collision>
  </link>
  <joint
    name="joint_2"
    type="prismatic">
    <origin
      xyz="-1.4856 0.7608 -0.3294"
      rpy="-1.2071 0 -1.5708" />
    <parent
      link="link_2" />
    <child
      link="link_3" />
    <axis
      xyz="0 1 0" />
    <limit
      lower="0"
      upper="0"
      effort="0"
      velocity="0" />
  </joint>
  <link
    name="link_4">
    <inertial>
      <origin
        xyz="0.000673418006044146 -0.0599442350829793 1.53948213466037E-06"
        rpy="0 0 0" />
      <mass
        value="0.799340963584629" />
      <inertia
        ixx="0.00140895567082913"
        ixy="-2.46582892500392E-10"
        ixz="-3.19145862384617E-07"
        iyy="0.00136374082161553"
        iyz="8.63181848370783E-08"
        izz="0.00189396258791085" />
    </inertial>
    <visual>
      <origin
        xyz="0 0 0"
        rpy="0 0 0" />
      <geometry>
        <mesh
          filename="D:\URDF\URDF_REV_3\meshes\link_4.STL" />
      </geometry>
      <material
        name="">
        <color
          rgba="0.792156862745098 0.819607843137255 0.933333333333333 1" />
      </material>
    </visual>
    <collision>
      <origin
        xyz="0 0 0"
        rpy="0 0 0" />
      <geometry>
        <mesh
          filename="D:\URDF\URDF_REV_3\meshes\link_4.STL" />
      </geometry>
    </collision>
  </link>
  <joint
    name="joint_3"
    type="revolute">
    <origin
      xyz="0.66729 0 1.284"
      rpy="0 -1.5708 0" />
    <parent
      link="link_3" />
    <child
      link="link_4" />
    <axis
      xyz="0 1 0" />
    <limit
      lower="0"
      upper="6.28"
      effort="0"
      velocity="0" />
  </joint>
  <link
    name="link_5">
    <inertial>
      <origin
        xyz="0.00225496730591113 -0.00504539183958563 0.00118990845808598"
        rpy="0 0 0" />
      <mass
        value="0.0767192011363821" />
      <inertia
        ixx="1.38646242656541E-05"
        ixy="-1.6525294997491E-06"
        ixz="-1.40077415272848E-09"
        iyy="1.68514625615022E-05"
        iyz="4.51062754914492E-10"
        izz="8.89573577148287E-06" />
    </inertial>
    <visual>
      <origin
        xyz="0 0 0"
        rpy="0 0 0" />
      <geometry>
        <mesh
          filename="D:\URDF\URDF_REV_3\meshes\link_5.STL" />
      </geometry>
      <material
        name="">
        <color
          rgba="0.792156862745098 0.819607843137255 0.933333333333333 1" />
      </material>
    </visual>
    <collision>
      <origin
        xyz="0 0 0"
        rpy="0 0 0" />
      <geometry>
        <mesh
          filename="D:\URDF\URDF_REV_3\meshes\link_5.STL" />
      </geometry>
    </collision>
  </link>
  <joint
    name="joint_4"
    type="revolute">
    <origin
      xyz="0 -0.11199 0"
      rpy="3.1416 0 -2.7223" />
    <parent
      link="link_4" />
    <child
      link="link_5" />
    <axis
      xyz="0 0 1" />
    <limit
      lower="-1.5"
      upper="1.5"
      effort="0"
      velocity="0" />
  </joint>
  <link
    name="link_6">
    <inertial>
      <origin
        xyz="0.0428142748520131 -0.12789476524092 0.0179248371485474"
        rpy="0 0 0" />
      <mass
        value="0.606420422229759" />
      <inertia
        ixx="0.000789035613576881"
        ixy="9.60678149879342E-05"
        ixz="-0.000114338599467818"
        iyy="0.0006417786887188"
        iyz="-8.03880311486961E-05"
        izz="0.001169691782768" />
    </inertial>
    <visual>
      <origin
        xyz="0 0 0"
        rpy="0 0 0" />
      <geometry>
        <mesh
          filename="D:\URDF\URDF_REV_3\meshes\link_6.STL" />
      </geometry>
      <material
        name="">
        <color
          rgba="0.792156862745098 0.819607843137255 0.933333333333333 1" />
      </material>
    </visual>
    <collision>
      <origin
        xyz="0 0 0"
        rpy="0 0 0" />
      <geometry>
        <mesh
          filename="D:\URDF\URDF_REV_3\meshes\link_6.STL" />
      </geometry>
    </collision>
  </link>
  <joint
    name="joint_5"
    type="revolute">
    <origin
      xyz="0 0.01 0"
      rpy="-0.14482 0.31311 -0.022898" />
    <parent
      link="link_5" />
    <child
      link="link_6" />
    <axis
      xyz="0.40712 -0.91338 0" />
    <limit
      lower="0"
      upper="6.28"
      effort="0"
      velocity="0" />
  </joint>
  <link
    name="grip_right">
    <inertial>
      <origin
        xyz="-0.0466538999893571 0.000857632028928412 -0.0322039277317805"
        rpy="0 0 0" />
      <mass
        value="0.115527039569298" />
      <inertia
        ixx="0.000163171715893224"
        ixy="-6.62861989462738E-19"
        ixz="-0.000119398657777974"
        iyy="0.000283429805434103"
        iyz="-1.37532532255971E-19"
        izz="0.000160973078577351" />
    </inertial>
    <visual>
      <origin
        xyz="0 0 0"
        rpy="0 0 0" />
      <geometry>
        <mesh
          filename="D:\URDF\URDF_REV_3\meshes\grip_right.STL" />
      </geometry>
      <material
        name="">
        <color
          rgba="0.792156862745098 0.819607843137255 0.933333333333333 1" />
      </material>
    </visual>
    <collision>
      <origin
        xyz="0 0 0"
        rpy="0 0 0" />
      <geometry>
        <mesh
          filename="D:\URDF\URDF_REV_3\meshes\grip_right.STL" />
      </geometry>
    </collision>
  </link>
  <joint
    name="joint_6"
    type="revolute">
    <origin
      xyz="0.089228 -0.15179 0.0070579"
      rpy="1.3609 0.27455 2.8949" />
    <parent
      link="link_6" />
    <child
      link="grip_right" />
    <axis
      xyz="0 1 0" />
    <limit
      lower="-1.5"
      upper="0"
      effort="0"
      velocity="0" />
  </joint>
  <link
    name="grip_left">
    <inertial>
      <origin
        xyz="0.0465657171128868 0.000857632028879785 -0.0322524237347066"
        rpy="0 0 0" />
      <mass
        value="0.115527039569299" />
      <inertia
        ixx="0.000164170738017028"
        ixy="5.61155268971395E-19"
        ixz="0.000119694294570289"
        iyy="0.000283984364729587"
        iyz="-4.41510200685804E-19"
        izz="0.000160528615749031" />
    </inertial>
    <visual>
      <origin
        xyz="0 0 0"
        rpy="0 0 0" />
      <geometry>
        <mesh
          filename="D:\URDF\URDF_REV_3\meshes\grip_left.STL" />
      </geometry>
      <material
        name="">
        <color
          rgba="0.792156862745098 0.819607843137255 0.933333333333333 1" />
      </material>
    </visual>
    <collision>
      <origin
        xyz="0 0 0"
        rpy="0 0 0" />
      <geometry>
        <mesh
          filename="D:\URDF\URDF_REV_3\meshes\grip_left.STL" />
      </geometry>
    </collision>
  </link>
  <joint
    name="joint_7"
    type="revolute">
    <origin
      xyz="0.046235 -0.17095 -0.0098037"
      rpy="1.7801 0.27504 -2.0587" />
    <parent
      link="link_6" />
    <child
      link="grip_left" />
    <axis
      xyz="0 1 0" />
    <limit
      lower="0"
      upper="1.5"
      effort="0"
      velocity="0" />
  </joint>
</robot>